Workbook
Name \C: #REF!
Name \C: #REF!
Name \C: #REF!
Name \C: #REF!
Name \C: #REF!
Name \C: #REF!
Name \C: #REF!
Name \C: #REF!
Name \C: #REF!
Name \C: #REF!
Name \C: #REF!
Name \C: #REF!
Name \C: #REF!
Name \C: #REF!
Name \C: #REF!
Name \C: #REF!
Name \C: #REF!
Name \C: #REF!
Name \C: #REF!
Name \C: #REF!
Name \C: #REF!
Name \C: #REF!
Name \C: #REF!
Name \C: #REF!
Name \C: #REF!
Name \C: #REF!
Name \C: #REF!
Name \C: #REF!
Name \C: #REF!
Name \C: #REF!
Name \C: #REF!
Name \C: #REF!
Name \C: #REF!
Name \C: #REF!
Name \C: #REF!
Name \C: #REF!
Name \C: #REF!
Name \C: #REF!
Name \C: #REF!
Name \C: #REF!
Name \C: #REF!
Name \C: #REF!
Name \C: #REF!
Name \D: #REF!
Name \D: #REF!
Name \D: #REF!
Name \D: #REF!
Name \D: #REF!
Name \D: #REF!
Name \D: #REF!
Name \D: #REF!
Name \D: #REF!
Name \D: #REF!
Name \D: #REF!
Name \D: #REF!
Name \D: #REF!
Name \D: #REF!
Name \D: #REF!
Name \D: #REF!
Name \D: #REF!

Sheet Content
C1: Українською | D1: English | E1: 1 | G1: Українською
C2: English | D2: Українською | G2: English
B3: =IF($E$1=1,C3,D3) -> Суми значень можуть не співпадати через заокруглення | C3: Суми значень можуть не співпадати через заокруглення | D3: Numbers may not add up due to rounding
B4: =IF($E$1=1,C4,D4) -> Якщо не позначено інше – пунктирна лінія в графіках означає попередній прогноз | C4: Якщо не позначено інше – пунктирна лінія в графіках означає попередній прогноз | D4: Dotted line in charts refers to previous forecast unless otherwise stated
A6: 0 | B6: =IF($E$1=1,C6,D6) -> Головне | C6: Головне | D6: Summary
A7: 0.1 | B7: ='0.1'!L1 -> Зміна ІСЦ (станом на кінець періоду, % р/р) та інфляційні цілі
A8: 0.2 | B8: ='0.2'!G1 -> Облікова ставка НБУ, середня, %
A10: 1 | B10: =IF($E$1=1,C10,D10) -> Інфляційний розвиток | C10: Інфляційний розвиток | D10: Inflation Developments
A11: 1.1 | B11: ='1.1'!K1 -> Споживча інфляція та оцінки основного інфляційного тренду*, % р/р
A12: 1.2 | B12: ='1.2'!J1 -> Окремі компоненти ІСЦ, % р/р
A13: 1.3 | B13: ='1.3'!M1 -> Внески в зміну цін на продукти харчування*, в. п.
A14: 1.4 | B14: ='1.4'!K1 -> Зміна цін на окремі групи харчових продуктів, % р/р
A15: 1.5 | B15: ='1.5'!J1 -> Роздрібні та гуртові* ціни на пальне в останні місяці, грн/л
A16: 1.6 | B16: ='1.6'!J1 -> Внески в зміну адміністративно регульованих цін, в. п.
A17: 1.7 | B17: ='1.7'!I1 -> Окремі компоненти адміністративної інфляції, % р/р
A18: 1.8 | B18: ='1.8'!I1 -> Інфляційні очікування на наступні 12 місяців та інфляція в річному вимірі, %
A19: 1.9 | B19: ='1.9'!H1 -> Індекс цін виробників (ІЦВ) та його компоненти, % р/р
A20: 1.10 | B20: ='1.10'!G1 -> Ціни на е/е для непобутових споживачів, грн/МВт•год
A21: 1.11 | B21: ='1.11'!H1 -> Компоненти БІСЦ, % р/р
A22: 1.12 | B22: ='1.12'!I1 -> Ануалізовані* зміни основних складових БІСЦ, %
A23: 1.13 | B23: ='1.13'!H1 -> Річна зміна середньої зарплати, %*
A24: 1.14 | B24: ='1.14'!I1 -> Зміна цін на окремі групи послуг, % р/р
A25: 1.15 | B25: ='1.15'!E1 -> Теплова карта БІСЦ*, %
A26: 1.16 | B26: ='1.16'!E1 -> Ануалізовані* зміни ІСЦ та БІСЦ, %
A27: 1.17 | B27: ='1.17'!H1 -> Базовий ІСЦ на кінець періоду, %
A28: 1.18 | B28: ='1.18'!F1 -> Компоненти продовольчої інфляції, зміна на кінець періоду, % р/р
A29: 1.19 | B29: ='1.19'!H1 -> Ціни на сирі продовольчі товари на кінець періоду, %
A30: 1.20 | B30: ='1.20'!G1 -> Окремі компоненти продовольчої інфляції та врожай, зміна на кінець періоду, % р/р
A31: 1.21 | B31: ='1.21'!G1 -> Адміністративно регульовані ціни на кінець періоду, %
A32: 1.22 | B32: ='1.22'!G1 -> Ціни на пальне на кінець періоду, %
A33: 1.23 | B33: ='1.23'!M1 -> ІСЦ на кінець періоду, %
A34: 1.24 | B34: ='1.24'!I1 -> Внески компонентів у річну зміну ІСЦ (в. п.)
A36: 2 | B36: =IF($E$1=1,C36,D36) -> Економічний розвиток | C36: Економічний розвиток | D36: Economic Developments
A37: 2.1 | B37: ='2.1'!H1 -> Індекс промислової продукції за видами економічної діяльності*, % р/р
A38: 2.2 | B38: ='2.2'!K1 -> Індекс ділових очікувань за видами діяльності, %
A39: 2.3 | B39: ='2.3'!F1 -> Індекс вантажо- та пасажирообігу*, % р/р
A40: 2.4 | B40: ='2.4'!H1 -> Індекс будівельної продукції*, % р/р
A41: 2.5 | B41: ='2.5'!F1 -> Нестача працівників як проблема бізнесу, % відповідей
A42: 2.6 | B42: ='2.6'!K1 -> Брак кваліфікованих працівників як чинник, що обмежує спроможності збільшувати виробництво, % відповідей
A43: 2.7 | B43: ='2.7'!H1 -> Сальдо СЗДУ за різними вимірами* та реальний ВВП
...

Sheet 0.1
A1: << | C1: =IF(Content!$E$1=1,C2,C3) -> ІСЦ | D1: =IF(Content!$E$1=1,D2,D3) -> Попередній прогноз | E1: =IF(Content!$E$1=1,E2,E3) -> Цільовий діапазон | I1: =IF(Content!$E$1=1,I2,I3) -> Ціль | L1: =IF(Content!$E$1=1,L2,L3) -> Зміна ІСЦ (станом на кінець періоду, % р/р) та інфляційні цілі | V1: =IF(Content!$E$1=1,V2,V3) -> Прогноз | W1: =IF(Content!$E$1=1,W2,W3) -> Горизонт монетарної політики
C2: ІСЦ | D2: Попередній прогноз | E2: Цільовий діапазон | I2: Ціль | L2: Зміна ІСЦ (станом на кінець періоду, % р/р) та інфляційні цілі | V2: Прогноз | W2: Горизонт монетарної політики
C3: CPI | D3: Previous forecast | E3: Tolerance bands | I3: Target | L3: CPI growth (eop, % yoy) and inflation targets | V3: Forecast | W3: Monetary policy horizon
A4: I.17 | B4: I.17 | C4: 15.1 | E4: 9 | F4: 15 | G4: 6 | I4: 12
B5: II.17 | C5: 15.6 | E5: 9 | F5: 15 | G5: 6 | I5: 12
B6: III.17 | C6: 16.4 | E6: 7 | F6: 13 | G6: 6 | I6: 10
B7: IV.17 | C7: 13.7 | E7: 6 | F7: 10 | G7: 4 | I7: 8
A8: I.18 | B8: I.18 | C8: 13.2 | E8: 5.5 | F8: 9.5 | G8: 4 | I8: 7.5
B9: II.18 | C9: 9.9 | E9: 5 | F9: 9 | G9: 4 | I9: 7
B10: III.18 | C10: 8.9 | E10: 4.5 | F10: 8.5 | G10: 4 | I10: 6.5
B11: IV.18 | C11: 9.8 | E11: 4 | F11: 8 | G11: 4 | I11: 6
A12: I.19 | B12: I.19 | C12: 8.6 | E12: 3.75 | F12: 7.75 | G12: 4 | I12: 5.75
B13: II.19 | C13: 9 | E13: 3.5 | F13: 7.5 | G13: 4 | I13: 5.5
B14: III.19 | C14: 7.5 | E14: 3.25 | F14: 7.25 | G14: 4 | I14: 5.25
B15: IV.19 | C15: 4.1 | E15: 4 | F15: 6 | G15: 2 | I15: 5
A16: I.20 | B16: I.20 | C16: 2.3 | E16: 4 | F16: 6 | G16: 2 | I16: 5 | L16: =IF(Content!$E$1=1,L20,L19) -> Джерело: ДССУ, розрахунки НБУ.
B17: II.20 | C17: 2.4 | E17: 4 | F17: 6 | G17: 2 | I17: 5
B18: III.20 | C18: 2.3 | E18: 4 | F18: 6 | G18: 2 | I18: 5
B19: IV.20 | C19: 5 | E19: 4 | F19: 6 | G19: 2 | I19: 5 | L19: Source: SSSU, NBU staff estimates.
A20: I.21 | B20: I.21 | C20: 8.5 | E20: 4 | F20: 6 | G20: 2 | I20: 5 | L20: Джерело: ДССУ, розрахунки НБУ.
B21: II.21 | C21: 9.5 | E21: 4 | F21: 6 | G21: 2 | I21: 5
B22: III.21 | C22: 11 | E22: 4 | F22: 6 | G22: 2 | I22: 5
B23: IV.21 | C23: 10 | E23: 4 | F23: 6 | G23: 2 | I23: 5
A24: I.22 | B24: I.22 | C24: 13.7 | E24: 4 | F24: 6 | G24: 2 | I24: 5
B25: II.22 | C25: 21.5 | E25: 4 | F25: 6 | G25: 2 | I25: 5
B26: III.22 | C26: 24.6 | E26: 4 | F26: 6 | G26: 2 | I26: 5
B27: IV.22 | C27: 26.6 | E27: 4 | F27: 6 | G27: 2 | I27: 5
A28: I.23 | B28: I.23 | C28: 21.3 | E28: 4 | F28: 6 | G28: 2 | I28: 5
B29: II.23 | C29: 12.8 | E29: 4 | F29: 6 | G29: 2 | I29: 5
B30: III.23 | C30: 7.1 | E30: 4 | F30: 6 | G30: 2 | I30: 5
B31: IV.23 | C31: 5.1 | E31: 4 | F31: 6 | G31: 2 | I31: 5
A32: I.24 | B32: I.24 | C32: 3.2 | E32: 4 | F32: 6 | G32: 2 | I32: 5
B33: II.24 | C33: 4.8 | E33: 4 | F33: 6 | G33: 2 | I33: 5
B34: III.24 | C34: 8.6 | E34: 4 | F34: 6 | G34: 2 | I34: 5
B35: IV.24 | C35: 12 | E35: 5 | F35: 6 | I35: 5
A36: I.25 | B36: I.25 | C36: 14.6 | I36: 5
B37: II.25 | C37: 14.3 | I37: 5
B38: III.25 | C38: 11.9 | I38: 5
B39: IV.25 | C39: 8 | I39: 5
A40: I.26 | B40: I.26 | C40: 7.9 | D40: 7.9 | I40: 5
...

Sheet 0.2
A1: << | B1: =IF(Content!$E$1=1,B2,B3) -> Облікова ставка, % | C1: =IF(Content!$E$1=1,C2,C3) -> Попередній прогноз | G1: =IF(Content!$E$1=1,G2,G3) -> Облікова ставка НБУ, середня, %
B2: Облікова ставка, % | C2: Попередній прогноз | G2: Облікова ставка НБУ, середня, %
B3: Key policy rate, % | C3: Previous forecast | G3: NBU`s key policy rate, average, %
A4: I.19 | B4: 18 | C4: 18
B5: 17.6 | C5: 17.6
B6: 17 | C6: 17
B7: 15.3 | C7: 15.3
A8: I.20 | B8: 11.6 | C8: 11.6
B9: 8.1 | C9: 8.1
B10: 6 | C10: 6
B11: 6 | C11: 6
A12: I.21 | B12: 6.1 | C12: 6.1
B13: 7.3 | C13: 7.3
B14: 8 | C14: 8
B15: 8.6 | C15: 8.6
A16: I.22 | B16: 9.8 | C16: 9.8
B17: 14.7 | C17: 14.7
B18: 25 | C18: 25
B19: 25 | C19: 25 | G19: =IF(Content!$E$1=1,G20,G21) -> Джерело: розрахунки НБУ.
A20: I.23 | B20: 25 | C20: 25 | G20: Джерело: розрахунки НБУ.
B21: 25 | C21: 25 | G21: Source: NBU staff estimates.
B22: 22.5 | C22: 22.5
B23: 16.9
A24: I.24 | B24: 14.9
B25: 13.7
B26: 13
B27: 13.1
A28: I.25 | B28: 14.5
B29: 15.5
B30: 15.5
B31: 15.5
A32: I.26 | B32: 15.2
B33: 15 | C33: 15
B34: 15.4 | C34: 15
B35: 16 | C35: 15
A36: I.27 | B36: 16 | C36: 15
B37: 15.3 | C37: 14.3
B38: 14.6 | C38: 13.6
B39: 14 | C39: 13
A40: I.28 | B40: 13.2 | C40: 12.3
...

Sheet 1.1
A1: << | B1: =IF(Content!$E$1=1,B2,B3) -> ІСЦ | C1: =IF(Content!$E$1=1,C2,C3) -> Базовий ІСЦ | D1: =IF(Content!$E$1=1,D2,D3) -> Нижня межа діапазону | E1: =IF(Content!$E$1=1,E2,E3) -> Показники базової інфляції | F1: =IF(Content!$E$1=1,F2,F3) -> Ціль з інфляції | G1: =IF(Content!$E$1=1,G2,G3) -> Цільовий діапазон | H1: =IF(Content!$E$1=1,H2,H3) -> Верхня лінія цільового діапазону | K1: =IF(Content!$E$1=1,K2,K3) -> Споживча інфляція та оцінки основного інфляційного тренду*, % р/р
B2: ІСЦ | C2: Базовий ІСЦ | D2: Нижня межа діапазону | E2: Показники базової інфляції | F2: Ціль з інфляції | G2: Цільовий діапазон | H2: Верхня лінія цільового діапазону | K2: Споживча інфляція та оцінки основного інфляційного тренду*, % р/р
B3: CPI | C3: Core CPI | D3: Lower bound | E3: Core inflation measures | F3: Inflation target | G3: Target range | H3: Upper target bound | K3: Consumer inflation and estimates of the underlying inflation trends*, % yoy
A4: 45292 | B4: 4.7 | C4: 4.6 | D4: 3.7 | E4: 4.3 | F4: 5 | G4: 4 | H4: 6 | I4: 01.24
A5: 45323 | B5: 4.3 | C5: 4.5 | D5: 3.5 | E5: 4.3 | F5: 5 | G5: 4 | H5: 6
A6: 45352 | B6: 3.2 | C6: 4.2 | D6: 3.1 | E6: 4.4 | F6: 5 | G6: 4 | H6: 6
A7: 45383 | B7: 3.2 | C7: 4.4 | D7: 3.1 | E7: 4.2 | F7: 5 | G7: 4 | H7: 6
A8: 45413 | B8: 3.3 | C8: 4.4 | D8: 3.4 | E8: 4 | F8: 5 | G8: 4 | H8: 6
A9: 45444 | B9: 4.8 | C9: 5 | D9: 3.6 | E9: 4 | F9: 5 | G9: 4 | H9: 6
A10: 45474 | B10: 5.4 | C10: 5.7 | D10: 2.9 | E10: 4.9 | F10: 5 | G10: 4 | H10: 6 | I10: 07.24
A11: 45505 | B11: 7.5 | C11: 6.5 | D11: 4.7 | E11: 3.6 | F11: 5 | G11: 4 | H11: 6
A12: 45536 | B12: 8.6 | C12: 7.3 | D12: 5.3 | E12: 3.8 | F12: 5
A13: 45566 | B13: 9.7 | C13: 8.3 | D13: 5.9 | E13: 4 | F13: 5
A14: 45597 | B14: 11.2 | C14: 9.3 | D14: 6.7 | E14: 4.1 | F14: 5
A15: 45627 | B15: 12 | C15: 10.7 | D15: 7.7 | E15: 3.9 | F15: 5
A16: 45658 | B16: 12.9 | C16: 11.7 | D16: 8.6 | E16: 3.8 | F16: 5 | I16: 01.25
A17: 45689 | B17: 13.4 | C17: 12 | D17: 9.1 | E17: 3.7 | F17: 5
A18: 45717 | B18: 14.6 | C18: 12.4 | D18: 9.6 | E18: 3.8 | F18: 5
A19: 45748 | B19: 15.1 | C19: 12.1 | D19: 9.4 | E19: 4.2 | F19: 5 | K19: =IF(Content!$E$1=1,K32,K34) -> * Детальніше – в Інфляційному звіті за січень 2017 року (стор. 20, 21). Цільовий діапазон діяв до серпня 2024 року включно.
A20: 45778 | B20: 15.9 | C20: 12.3 | D20: 9.6 | E20: 4.6 | F20: 5 | K20: =IF(Content!$E$1=1,K33,K35) -> Джерело: ДССУ, розрахунки НБУ.
A21: 45809 | B21: 14.3 | C21: 12.1 | D21: 9.6 | E21: 4.7 | F21: 5
A22: 45839 | B22: 14.1 | C22: 11.7 | D22: 9.5 | E22: 4.8 | F22: 5 | I22: 07.25
A23: 45870 | B23: 13.2 | C23: 11.4 | D23: 9.1 | E23: 4.9 | F23: 5
A24: 45901 | B24: 11.9 | C24: 11 | D24: 8.6 | E24: 4.8 | F24: 5
A25: 45931 | B25: 10.9 | C25: 10.2 | D25: 7.8 | E25: 5.1 | F25: 5
A26: 45962 | B26: 9.3 | C26: 9.3 | D26: 6.8 | E26: 5.2 | F26: 5
A27: 45992 | B27: 8 | C27: 8 | D27: 5.9 | E27: 5 | F27: 5
A28: 46023 | B28: 7.4 | C28: 7 | D28: 5.8 | E28: 4.3 | F28: 5 | I28: 46023
A29: 46054 | B29: 7.6 | C29: 7 | D29: 6.2 | E29: 3.7 | F29: 5
A30: 46082 | B30: 7.9 | C30: 7.1 | D30: 6.3 | E30: 3.7 | F30: 5
A31: 46113 | B31: 8.6 | C31: 7.6 | D31: 7.1 | E31: 3.4 | F31: 5
A32: 46143 | B32: 8.2 | C32: 7.9 | D32: 7.4 | E32: 3.1 | F32: 5 | K32: * Детальніше – в Інфляційному звіті за січень 2017 року (стор. 20, 21). Цільовий діапазон діяв до серпня 2024 року включно.
A33: 46174 | B33: 7.2 | C33: 8.1 | D33: 7.3 | E33: 2.9 | F33: 5 | I33: 46174 | K33: Джерело: ДССУ, розрахунки НБУ.
K34: * Read more in the January 2017 Inflation Report (pages 20, 21). The target range remained in effect until August 2024 inclusive.
K35: Source: SSSU, NBU staff estimates.

Sheet 1.2
A1: << | B1: =IF(Content!$E$1=1,B2,B3) -> Оброблені продукти | C1: =IF(Content!$E$1=1,C2,C3) -> Сирі продукти | D1: =IF(Content!$E$1=1,D2,D3) -> Адміністративно регульовані ціни | E1: =IF(Content!$E$1=1,E2,E3) -> Непродовольчі товари | F1: =IF(Content!$E$1=1,F2,F3) -> Послуги | G1: =IF(Content!$E$1=1,G2,G3) -> Ціни на паливо | J1: =IF(Content!$E$1=1,J2,J3) -> Окремі компоненти ІСЦ, % р/р
B2: Оброблені продукти | C2: Сирі продукти | D2: Адміністративно регульовані ціни | E2: Непродовольчі товари | F2: Послуги | G2: Ціни на паливо | J2: Окремі компоненти ІСЦ, % р/р
B3: Processed foods | C3: Raw foods | D3: Administered prices | E3: Nonfood products | F3: Services | G3: Fuel prices | J3: Selected CPI components, % yoy
A4: 45292 | B4: 5.5 | C4: 2.1 | D4: 10.4 | E4: -0.2 | F4: 10.1 | G4: -0.1 | H4: 01.24
A5: 45323 | B5: 5.6 | C5: -0.3 | D5: 10.1 | E5: -0.5 | F5: 9.8 | G5: 5
A6: 45352 | B6: 5.3 | C6: -4.9 | D6: 9.9 | E6: -0.9 | F6: 9.7 | G6: 11.2
A7: 45383 | B7: 5.5 | C7: -6.5 | D7: 9.5 | E7: -0.6 | F7: 9.7 | G7: 18.1
A8: 45413 | B8: 5.3 | C8: -6.6 | D8: 9.4 | E8: -0.3 | F8: 9.7 | G8: 22.5
A9: 45444 | B9: 5.9 | C9: -6.5 | D9: 13.3 | E9: 0.4 | F9: 9.9 | G9: 25.5
A10: 45474 | B10: 6.5 | C10: -4.8 | D10: 13.4 | E10: 1.2 | F10: 10.3 | G10: 17.6 | H10: 07.24
A11: 45505 | B11: 7.4 | C11: 3.7 | D11: 13.7 | E11: 1.9 | F11: 10.5 | G11: 10.1
A12: 45536 | B12: 8.9 | C12: 7.1 | D12: 14 | E12: 2.2 | F12: 10.9 | G12: 6
A13: 45566 | B13: 10.7 | C13: 10.5 | D13: 14.5 | E13: 2.9 | F13: 11 | G13: 3.2
A14: 45597 | B14: 12.5 | C14: 15.7 | D14: 15.1 | E14: 3.6 | F14: 11.2 | G14: 0.6
A15: 45627 | B15: 14.7 | C15: 13.2 | D15: 16.3 | E15: 4.1 | F15: 12.5 | G15: 4.8
A16: 45658 | B16: 15.9 | C16: 11.8 | D16: 17.5 | E16: 4.3 | F16: 14.2 | G16: 12.1 | H16: 01.25
A17: 45689 | B17: 16.7 | C17: 13 | D17: 18.1 | E17: 4.4 | F17: 14.3 | G17: 13.9
A18: 45717 | B18: 17.3 | C18: 17 | D18: 19 | E18: 4.7 | F18: 14.6 | G18: 9.9
A19: 45748 | B19: 17.3 | C19: 22.2 | D19: 19.5 | E19: 3.8 | F19: 14.6 | G19: 3.7 | J19: =IF(Content!$E$1=1,J21,J23) -> Джерело: ДССУ, розрахунки НБУ.
A20: 45778 | B20: 18 | C20: 26.4 | D20: 19.8 | E20: 3.8 | F20: 14.6 | G20: 1.2
A21: 45809 | B21: 18.2 | C21: 28.7 | D21: 10.9 | E21: 3.6 | F21: 14.4 | G21: 3.1 | J21: Джерело: ДССУ, розрахунки НБУ.
A22: 45839 | B22: 18 | C22: 28 | D22: 11 | E22: 3.2 | F22: 14 | G22: 6.7 | H22: 07.25
A23: 45870 | B23: 17.7 | C23: 23.9 | D23: 10.8 | E23: 2.8 | F23: 14.1 | G23: 6 | J23: Source: SSSU, NBU staff estimates.
A24: 45901 | B24: 16.8 | C24: 18.1 | D24: 10.7 | E24: 2.3 | F24: 14.1 | G24: 4.7
A25: 45931 | B25: 15.6 | C25: 15.2 | D25: 10.6 | E25: 1.6 | F25: 13.8 | G25: 3.9
A26: 45962 | B26: 13.9 | C26: 9.6 | D26: 10.4 | E26: 0.8 | F26: 13.4 | G26: 5.3
A27: 45992 | B27: 12.1 | C27: 7.4 | D27: 9.7 | E27: 0 | F27: 12.3 | G27: 6.4
A28: 46023 | B28: 10.8 | C28: 8.2 | D28: 9.1 | E28: -0.4 | F28: 11.2 | G28: 5.7 | H28: 46023
A29: 46054 | B29: 9.9 | C29: 9.6 | D29: 8.8 | E29: -0.4 | F29: 12.3 | G29: 8
A30: 46082 | B30: 10 | C30: 8.4 | D30: 8.6 | E30: -0.5 | F30: 12.8 | G30: 23.4
A31: 46113 | B31: 10.2 | C31: 8.3 | D31: 9.4 | E31: 0.3 | F31: 13.3 | G31: 36.1
A32: 46143 | B32: 10.4 | C32: 4.6 | D32: 10.2 | E32: 0.3 | F32: 13.6 | G32: 38.7
A33: 46174 | B33: 10.4 | C33: -0.2 | D33: 10.7 | E33: 0.5 | F33: 13.7 | G33: 33.4 | H33: 46174

Sheet 1.3
A1: << | B1: =IF(Content!$E$1=1,B2,B3) -> Продукти харчування, % р/р | C1: =IF(Content!$E$1=1,C2,C3) -> Хліб, крупи, макарони | D1: =IF(Content!$E$1=1,D2,D3) -> Молочні продукти | E1: =IF(Content!$E$1=1,E2,E3) -> Яйця | F1: =IF(Content!$E$1=1,F2,F3) -> М'ясо та м’ясопродукти | G1: =IF(Content!$E$1=1,G2,G3) -> Риба та рибопродукти | H1: =IF(Content!$E$1=1,H2,H3) -> Овочі | I1: =IF(Content!$E$1=1,I2,I3) -> Фрукти | J1: =IF(Content!$E$1=1,J2,J3) -> Інше | M1: =IF(Content!$E$1=1,M2,M3) -> Внески в зміну цін на продукти харчування*, в. п.
B2: Продукти харчування, % р/р | C2: Хліб, крупи, макарони | D2: Молочні продукти | E2: Яйця | F2: М'ясо та м’ясопродукти | G2: Риба та рибопродукти | H2: Овочі | I2: Фрукти | J2: Інше | M2: Внески в зміну цін на продукти харчування*, в. п.
B3: Foods, % yoy | C3: Bread, cereals, pasta | D3: Dairy products | E3: Eggs | F3: Meat and meat products | G3: Fish and fish products | H3: Vegetables | I3: Fruits | J3: Other | M3: Contributions to the annual change in food prices*, pp
A4: 45292 | B4: 3.7 | C4: -0.7 | D4: 1.1 | E4: -0.5 | F4: 2 | G4: 0.3 | H4: 1.1 | I4: 0.1 | J4: 0.3 | K4: 45292
A5: 45323 | B5: 2.6 | C5: -0.5 | D5: 1.1 | E5: -0.5 | F5: 1.5 | G5: 0.2 | H5: 0.5 | I5: 0 | J5: 0.1
A6: 45352 | B6: 0.2 | C6: -0.1 | D6: 0.1 | E6: -0.1 | F6: 0.2 | G6: 0 | H6: 0 | I6: 0 | J6: 0
A7: 45383 | B7: -0.5 | C7: 0.2 | D7: -0.5 | E7: 0.4 | F7: -0.3 | G7: -0.1 | H7: 0 | I7: -0.1 | J7: 0
A8: 45413 | B8: -0.5 | C8: 0.1 | D8: -0.3 | E8: 0.2 | F8: -0.2 | G8: -0.1 | H8: -0.1 | I8: -0.1 | J8: 0
A9: 45444 | B9: -0.1 | C9: 0 | D9: -0.1 | E9: 0 | F9: 0 | G9: 0 | H9: 0 | I9: 0 | J9: 0
A10: 45474 | B10: 1.2 | C10: 0.2 | D10: 0.8 | E10: -0.3 | F10: -0.1 | G10: 0.2 | H10: -0.4 | I10: 0.4 | J10: 0.4 | K10: 45474
A11: 45505 | B11: 6 | C11: 0.6 | D11: 1.6 | E11: -0.5 | F11: -0.2 | G11: 0.4 | H11: 2.6 | I11: 0.5 | J11: 0.9
A12: 45536 | B12: 8.5 | C12: 0.9 | D12: 2 | E12: -0.5 | F12: -0.1 | G12: 0.5 | H12: 3.6 | I12: 0.9 | J12: 1.2
A13: 45566 | B13: 10.8 | C13: 1.1 | D13: 2.4 | E13: -0.4 | F13: 0.1 | G13: 0.6 | H13: 4.1 | I13: 1.4 | J13: 1.5
A14: 45597 | B14: 14.3 | C14: 1.4 | D14: 2.9 | E14: 0.9 | F14: 0.5 | G14: 0.7 | H14: 4.3 | I14: 1.5 | J14: 2.1
A15: 45627 | B15: 14.1 | C15: 1.8 | D15: 3.3 | E15: 0.4 | F15: 0.8 | G15: 0.8 | H15: 3.2 | I15: 1 | J15: 2.8
A16: 45658 | B16: 14.3 | C16: 2 | D16: 3.5 | E16: -0.1 | F16: 1.4 | G16: 0.8 | H16: 2.6 | I16: 0.8 | J16: 3.3 | K16: 45658
A17: 45689 | B17: 15.2 | C17: 2.1 | D17: 3.5 | E17: 0 | F17: 1.7 | G17: 0.8 | H17: 2.4 | I17: 0.9 | J17: 3.6 | M17: =IF(Content!$E$1=1,M21,M22) -> * Містять як сирі, так і оброблені продукти харчування.
A18: 45717 | B18: 17.4 | C18: 2.2 | D18: 3.5 | E18: 1 | F18: 2 | G18: 0.8 | H18: 2.7 | I18: 1.1 | J18: 3.9 | M18: =IF(Content!$E$1=1,M19,M20) -> Джерело: ДССУ, розрахунки НБУ.
A19: 45748 | B19: 19.8 | C19: 2.3 | D19: 3.4 | E19: 1.4 | F19: 2.9 | G19: 0.8 | H19: 3.1 | I19: 1.7 | J19: 4.1 | M19: Джерело: ДССУ, розрахунки НБУ.
A20: 45778 | B20: 22.1 | C20: 2.4 | D20: 3.4 | E20: 1.5 | F20: 4.2 | G20: 0.8 | H20: 3.1 | I20: 2.4 | J20: 4.3 | M20: Source: SSSU, NBU staff estimates.
A21: 45809 | B21: 23.2 | C21: 2.3 | D21: 3.4 | E21: 1.2 | F21: 5.2 | G21: 0.8 | H21: 2.2 | I21: 3.7 | J21: 4.3 | M21: * Містять як сирі, так і оброблені продукти харчування.
A22: 45839 | B22: 22.6 | C22: 2.1 | D22: 3.4 | E22: 1.6 | F22: 5.4 | G22: 0.8 | H22: 1.6 | I22: 3.7 | J22: 4 | K22: 45839 | M22: * Includes both raw and processed foods.
A23: 45870 | B23: 20.5 | C23: 1.9 | D23: 3.4 | E23: 1.5 | F23: 5.6 | G23: 0.9 | H23: -0.1 | I23: 3.3 | J23: 3.9
A24: 45901 | B24: 17.4 | C24: 1.8 | D24: 3.1 | E24: 1.1 | F24: 5.6 | G24: 1 | H24: -1.3 | I24: 2.1 | J24: 3.9
A25: 45931 | B25: 15.6 | C25: 1.8 | D25: 2.7 | E25: 1 | F25: 5.7 | G25: 1 | H25: -1.9 | I25: 1.5 | J25: 3.9
A26: 45962 | B26: 12.1 | C26: 1.6 | D26: 2 | E26: 0.1 | F26: 5.2 | G26: 1 | H26: -2.6 | I26: 1.3 | J26: 3.5
A27: 45992 | B27: 10.2 | C27: 1.4 | D27: 1.4 | E27: 0.3 | F27: 4.8 | G27: 1 | H27: -2.9 | I27: 1 | J27: 3.2
A28: 46023 | B28: 9.7 | C28: 1.3 | D28: 1 | E28: 0.6 | F28: 4 | G28: 1 | H28: -2 | I28: 1.1 | J28: 2.8 | K28: 46023
A29: 46054 | B29: 9.9 | C29: 1.3 | D29: 0.7 | E29: 0.6 | F29: 3.5 | G29: 1 | H29: -0.9 | I29: 1.3 | J29: 2.4
A30: 46082 | B30: 9.5 | C30: 1.4 | D30: 0.6 | E30: 0.4 | F30: 3.2 | G30: 1.1 | H30: -0.8 | I30: 1.1 | J30: 2.4
A31: 46113 | B31: 9.6 | C31: 2 | D31: 0.6 | E31: 0.4 | F31: 2.8 | G31: 1.1 | H31: -0.4 | I31: 0.7 | J31: 2.3
A32: 46143 | B32: 7.9 | C32: 2.2 | D32: 0.5 | E32: 0.2 | F32: 1.6 | G32: 1.1 | H32: -0.3 | I32: 0.4 | J32: 2.2
A33: 46174 | B33: 5.6 | C33: 2 | D33: 0.5 | E33: -0.3 | F33: 0.9 | G33: 1 | H33: 0 | I33: -0.4 | J33: 2 | K33: 46174

Sheet 1.4
A1: << | B1: =IF(Content!$E$1=1,B2,B3) -> Крупи | C1: =IF(Content!$E$1=1,C2,C3) -> М’ясо та м’ясопродукти | D1: =IF(Content!$E$1=1,D2,D3) -> Риба та рибопродукти | E1: =IF(Content!$E$1=1,E2,E3) -> Молочні продукти | F1: =IF(Content!$E$1=1,F2,F3) -> Овочі | G1: =IF(Content!$E$1=1,G2,G3) -> Фрукти | H1: =IF(Content!$E$1=1,H2,H3) -> Цукор | K1: =IF(Content!$E$1=1,K2,K3) -> Зміна цін на окремі групи харчових продуктів, % р/р
B2: Крупи | C2: М’ясо та м’ясопродукти | D2: Риба та рибопродукти | E2: Молочні продукти | F2: Овочі | G2: Фрукти | H2: Цукор | K2: Зміна цін на окремі групи харчових продуктів, % р/р
B3: Cereals | C3: Meat and meat products | D3: Fish and fish products | E3: Dairy products | F3: Vegetables | G3: Fruits | H3: Sugar | K3: Changes in prices for selected food product groups, % yoy
A4: 45292 | B4: -40.5 | C4: 10.2 | D4: 5.3 | E4: 9.1 | F4: 13.1 | G4: 2.3 | H4: -8.2 | J4: 01.24
A5: 45323 | B5: -39.8 | C5: 9.1 | D5: 4.7 | E5: 10.2 | F5: 3.7 | G5: 1.3 | H5: -10.4
A6: 45352 | B6: -38.7 | C6: 7.7 | D6: 4.5 | E6: 9.8 | F6: -12.2 | G6: 4.9 | H6: -13.1
A7: 45383 | B7: -38.5 | C7: 4.2 | D7: 5.1 | E7: 10.3 | F7: -13.9 | G7: 7 | H7: -14.9
A8: 45413 | B8: -35.4 | C8: 2.9 | D8: 5.4 | E8: 9.9 | F8: -17.4 | G8: 8.7 | H8: -14.1
A9: 45444 | B9: -30.2 | C9: 0.4 | D9: 6.4 | E9: 10.2 | F9: -17.9 | G9: 11 | H9: -11.3
A10: 45474 | B10: -24 | C10: -0.7 | D10: 5.9 | E10: 10.3 | F10: -19.3 | G10: 14.1 | H10: -1.8 | J10: 07.24
A11: 45505 | B11: -21.3 | C11: -0.7 | D11: 6.7 | E11: 11.8 | F11: 36 | G11: 10.3 | H11: -1.6
A12: 45536 | B12: -16.1 | C12: -0.3 | D12: 8 | E12: 13.9 | F12: 56.4 | G12: 16 | H12: -4.6
A13: 45566 | B13: -6.5 | C13: 0.3 | D13: 9.3 | E13: 16.9 | F13: 62.1 | G13: 23.9 | H13: -6.6
A14: 45597 | B14: 4.6 | C14: 1.9 | D14: 11.1 | E14: 19.4 | F14: 62.9 | G14: 24.7 | H14: -3.6
A15: 45627 | B15: 13.6 | C15: 3.1 | D15: 12.1 | E15: 21.8 | F15: 48.3 | G15: 16.4 | H15: 0
A16: 45658 | B16: 16.7 | C16: 5.3 | D16: 11.6 | E16: 22.2 | F16: 33.9 | G16: 12.5 | H16: 2.3 | J16: 01.25
A17: 45689 | B17: 20.2 | C17: 6.8 | D17: 12.4 | E17: 22.3 | F17: 29.4 | G17: 14.1 | H17: 4.2
A18: 45717 | B18: 23.1 | C18: 8.5 | D18: 12.6 | E18: 22.2 | F18: 32.3 | G18: 16.9 | H18: 7.2
A19: 45748 | B19: 26.9 | C19: 12.6 | D19: 12.8 | E19: 21.7 | F19: 35.8 | G19: 25.3 | H19: 12.3
A20: 45778 | B20: 26.2 | C20: 18.2 | D20: 13.3 | E20: 21.7 | F20: 35.7 | G20: 33.5 | H20: 12.3 | K20: =IF(Content!$E$1=1,K21,K22) -> Джерело: ДССУ, розрахунки НБУ.
A21: 45809 | B21: 22 | C21: 22.9 | D21: 13.3 | E21: 21.7 | F21: 24.2 | G21: 51.7 | H21: 9 | K21: Джерело: ДССУ, розрахунки НБУ.
A22: 45839 | B22: 17.9 | C22: 24.2 | D22: 13.7 | E22: 21.6 | F22: 17.5 | G22: 52.1 | H22: -5.4 | J22: 07.25 | K22: Source: SSSU, NBU staff estimates.
A23: 45870 | B23: 17.3 | C23: 25.2 | D23: 14.5 | E23: 21 | F23: -2.5 | G23: 47.5 | H23: -8.5
A24: 45901 | B24: 17.7 | C24: 24.8 | D24: 15.6 | E24: 18.9 | F24: -16 | G24: 30.4 | H24: -8.2
A25: 45931 | B25: 21.9 | C25: 25.2 | D25: 16.2 | E25: 15.8 | F25: -21.5 | G25: 22.1 | H25: -6.6
A26: 45962 | B26: 19.9 | C26: 23.1 | D26: 16.7 | E26: 12.1 | F26: -27.8 | G26: 20.2 | H26: -7.6
A27: 45992 | B27: 19.6 | C27: 21 | D27: 16.5 | E27: 7.9 | F27: -29.8 | G27: 15.2 | H27: -9.7
A28: 46023 | B28: 23.2 | C28: 18.5 | D28: 17.4 | E28: 6.3 | F28: -23.7 | G28: 16.9 | H28: -10.3 | J28: 46023
A29: 46054 | B29: 27.7 | C29: 16.4 | D29: 17.9 | E29: 4.5 | F29: -14.6 | G29: 21.9 | H29: -10.8
A30: 46082 | B30: 34.8 | C30: 15.3 | D30: 19.3 | E30: 4.3 | F30: -15.1 | G30: 17.1 | H30: -12
A31: 46113 | B31: 63.7 | C31: 13.2 | D31: 20.5 | E31: 4 | F31: -14.3 | G31: 10.4 | H31: -10.8
A32: 46143 | B32: 77 | C32: 7.9 | D32: 21 | E32: 4.1 | F32: -16.8 | G32: 4.3 | H32: -10.3
A33: 46174 | B33: 72.9 | C33: 4.4 | D33: 21.4 | E33: 4.1 | F33: -12.8 | G33: -9.3 | H33: -11.3 | J33: 46174

Sheet 1.5
A1: << | B1: =IF(Content!$E$1=1,B2,B3) -> Роздріб на АЗС, грн/л | E1: =IF(Content!$E$1=1,E2,E3) -> Гуртові ціни, грн/л | J1: =IF(Content!$E$1=1,J2,J3) -> Роздрібні та гуртові* ціни на пальне в останні місяці, грн/л
B2: Роздріб на АЗС, грн/л | E2: Гуртові ціни, грн/л | J2: Роздрібні та гуртові* ціни на пальне в останні місяці, грн/л
B3: Retail price at gas stations, UAH/L | E3: Wholesale prices, UAH/L | J3: Retail and wholesale* fuel prices in recent months, UAH/L
B4: =IF(Content!$E$1=1,B5,B6) -> A-95 | C4: =IF(Content!$E$1=1,C5,C6) -> ДП | D4: =IF(Content!$E$1=1,D5,D6) -> Газ | E4: =IF(Content!$E$1=1,E5,E6) -> A-95 | F4: =IF(Content!$E$1=1,F5,F6) -> ДП | G4: =IF(Content!$E$1=1,G5,G6) -> Газ
B5: A-95 | C5: ДП | D5: Газ | E5: A-95 | F5: ДП | G5: Газ
B6: A-95 | C6: Diesel | D6: LPG | E6: A-95 | F6: Diesel | G6: LPG
A7: 46055 | B7: 60.65 | C7: 60.26 | D7: 38.34 | E7: 56.83 | F7: 53.03 | G7: 32.59
A8: 46056 | B8: 60.66 | C8: 60.25 | D8: 38.34 | E8: 55.48 | F8: 52.9 | G8: 32.61
A9: 46057 | B9: 60.72 | C9: 60.3 | D9: 38.34 | E9: 54.73 | F9: 52.76 | G9: 32.62
A10: 46058 | B10: 60.72 | C10: 60.35 | D10: 38.36 | E10: 54.04 | F10: 52.64 | G10: 32.48
A11: 46059 | B11: 60.8 | C11: 60.42 | D11: 38.35 | E11: 54.47 | F11: 52.55 | G11: 32.38
A12: 46062 | B12: 60.87 | C12: 60.5 | D12: 38.43 | E12: 54.47 | F12: 52.22 | G12: 32.25
A13: 46063 | B13: 60.91 | C13: 60.56 | D13: 38.44 | E13: 54.35 | F13: 52.26 | G13: 32.17
A14: 46064 | B14: 60.91 | C14: 60.57 | D14: 38.46 | E14: 54.24 | F14: 52.26 | G14: 32.25
A15: 46065 | B15: 60.93 | C15: 60.59 | D15: 38.47 | E15: 54.51 | F15: 52.37 | G15: 32.21
A16: 46066 | B16: 60.96 | C16: 60.62 | D16: 38.5 | E16: 53.26 | F16: 51.97 | G16: 32.55
A17: 46069 | B17: 60.96 | C17: 60.64 | D17: 38.51 | E17: 52.51 | F17: 51.9 | G17: 32.43
A18: 46070 | B18: 60.95 | C18: 60.63 | D18: 38.5 | E18: 52.42 | F18: 52 | G18: 32.42
A19: 46071 | B19: 60.94 | C19: 60.61 | D19: 38.5 | E19: 52 | F19: 51.95 | G19: 32.38 | J19: =IF(Content!$E$1=1,J22,J23) -> * Роздрібні – суцільні лінії, гуртові – пунктир.
A20: 46072 | B20: 60.94 | C20: 60.61 | D20: 38.51 | E20: 52.3 | F20: 52.72 | G20: 32.33 | J20: =IF(Content!$E$1=1,J24,J25) -> Джерело: Консалтингова група “А-95”.
A21: 46073 | B21: 60.93 | C21: 60.6 | D21: 38.51 | E21: 52.5 | F21: 53.32 | G21: 32.42
A22: 46076 | B22: 61.46 | C22: 61.15 | D22: 38.52 | E22: 52.5 | F22: 53.08 | G22: 32.54 | J22: * Роздрібні – суцільні лінії, гуртові – пунктир.
A23: 46077 | B23: 61.55 | C23: 61.24 | D23: 38.52 | E23: 52.46 | F23: 54.12 | G23: 32.59 | J23: * Retail – solid lines; wholesale – dotted lines.
A24: 46078 | B24: 61.78 | C24: 61.48 | D24: 38.52 | E24: 52.42 | F24: 54.3 | G24: 32.55 | J24: Джерело: Консалтингова група “А-95”.
A25: 46079 | B25: 61.83 | C25: 61.55 | D25: 38.51 | E25: 52.31 | F25: 54.36 | G25: 32.55 | J25: Source: A-95 Consulting Group.
A26: 46080 | B26: 61.84 | C26: 61.6 | D26: 38.5 | E26: 52.76 | F26: 54.65 | G26: 32.64
A27: 46083 | B27: 63.13 | C27: 62.96 | D27: 38.47 | E27: 54.77 | F27: 61.23 | G27: 32.74
A28: 46084 | B28: 65.07 | C28: 65.02 | D28: 39.05 | E28: 60.05 | F28: 67.34 | G28: 33.8
A29: 46085 | B29: 67.2 | C29: 67.4 | D29: 39.97 | E29: 61.36 | F29: 70.82 | G29: 34.66
A30: 46086 | B30: 68.28 | C30: 68.96 | D30: 40.23 | E30: 62.83 | F30: 71.75 | G30: 35.5
A31: 46087 | B31: 68.37 | C31: 69.1 | D31: 40.33 | E31: 61.53 | F31: 71.93 | G31: 35.57
A32: 46090 | B32: 68.97 | C32: 71.59 | D32: 40.66 | E32: 65.33 | F32: 82.77 | G32: 36.22
A33: 46091 | B33: 69.1 | C33: 72.92 | D33: 40.72 | E33: 62.66 | F33: 77.82 | G33: 39.41
A34: 46092 | B34: 69.09 | C34: 73.52 | D34: 41.36 | E34: 63.6 | F34: 74.29 | G34: 39.43
A35: 46093 | B35: 69.14 | C35: 74.37 | D35: 41.97 | E35: 62.9 | F35: 74.9 | G35: 40.93
A36: 46094 | B36: 69.14 | C36: 74.91 | D36: 42.5 | E36: 63.35 | F36: 76.78 | G36: 40.98
A37: 46097 | B37: 69.31 | C37: 76.76 | D37: 43.14 | E37: 64.57 | F37: 78 | G37: 41.52
... A136: 46234 | B136: 81.19 | C136: 91.99 | D136: 43.52 | E136: 80 | F136: 97.65 | G136: 39.23

Sheet 1.6
A1: << | B1: =IF(Content!$E$1=1,B2,B3) -> Адміністративно регульовані ціни, % р/р | C1: =IF(Content!$E$1=1,C2,C3) -> Алкогольні напої | D1: =IF(Content!$E$1=1,D2,D3) -> Тютюнові вироби | E1: =IF(Content!$E$1=1,E2,E3) -> Послуги ЖКГ | F1: =IF(Content!$E$1=1,F2,F3) -> Транспорт | G1: =IF(Content!$E$1=1,G2,G3) -> Іншe | J1: =IF(Content!$E$1=1,J2,J3) -> Внески в зміну адміністративно регульованих цін, в. п.
B2: Адміністративно регульовані ціни, % р/р | C2: Алкогольні напої | D2: Тютюнові вироби | E2: Послуги ЖКГ | F2: Транспорт | G2: Іншe | J2: Внески в зміну адміністративно регульованих цін, в. п.
B3: Administered prices, % yoy | C3: Alcoholic beverages | D3: Tobacco products | E3: Utilities | F3: Transport | G3: Other | J3: Contributions to the annual change in administered prices, pp
A4: 45292 | B4: 10.4 | C4: 0.7 | D4: 3.1 | E4: 4.8 | F4: 0.3 | G4: 1.4 | H4: 01.24
A5: 45323 | B5: 10.1 | C5: 0.5 | D5: 3.1 | E5: 4.9 | F5: 0.3 | G5: 1.4
A6: 45352 | B6: 9.9 | C6: 0.2 | D6: 3 | E6: 5 | F6: 0.3 | G6: 1.4
A7: 45383 | B7: 9.5 | C7: 0.1 | D7: 2.9 | E7: 5.1 | F7: 0.3 | G7: 1.1
A8: 45413 | B8: 9.4 | C8: -0.2 | D8: 2.8 | E8: 5.2 | F8: 0.3 | G8: 1.3
A9: 45444 | B9: 13.3 | C9: -0.2 | D9: 3.5 | E9: 7.9 | F9: 0.5 | G9: 1.6
A10: 45474 | B10: 13.4 | C10: -0.1 | D10: 3.4 | E10: 7.9 | F10: 0.5 | G10: 1.7 | H10: 07.24
A11: 45505 | B11: 13.7 | C11: -0.1 | D11: 3.2 | E11: 8 | F11: 0.6 | G11: 2
A12: 45536 | B12: 14 | C12: -0.1 | D12: 3.4 | E12: 8 | F12: 0.5 | G12: 2.1
A13: 45566 | B13: 14.5 | C13: 0.1 | D13: 3.8 | E13: 8.1 | F13: 0.6 | G13: 2
A14: 45597 | B14: 15.1 | C14: 0.2 | D14: 4 | E14: 8.2 | F14: 0.6 | G14: 2.1
A15: 45627 | B15: 16.3 | C15: 0.6 | D15: 4.3 | E15: 8.3 | F15: 0.7 | G15: 2.4
A16: 45658 | B16: 17.5 | C16: 0.7 | D16: 4.6 | E16: 8.3 | F16: 0.8 | G16: 3.1 | H16: 01.25
A17: 45689 | B17: 18.1 | C17: 0.8 | D17: 4.8 | E17: 8.3 | F17: 0.9 | G17: 3.3
A18: 45717 | B18: 19 | C18: 1.1 | D18: 5.1 | E18: 8.5 | F18: 1 | G18: 3.2
A19: 45748 | B19: 19.5 | C19: 1.1 | D19: 5.4 | E19: 8.7 | F19: 1 | G19: 3.2
A20: 45778 | B20: 19.8 | C20: 1.3 | D20: 5.6 | E20: 8.7 | F20: 1 | G20: 3.2 | J20: =IF(Content!$E$1=1,J21,J22) -> Джерело: ДССУ, розрахунки НБУ.
A21: 45809 | B21: 10.9 | C21: 1.1 | D21: 5.4 | E21: 0.4 | F21: 1 | G21: 3.1 | J21: Джерело: ДССУ, розрахунки НБУ.
A22: 45839 | B22: 11 | C22: 1.1 | D22: 5.8 | E22: 0.4 | F22: 0.9 | G22: 2.8 | H22: 07.25 | J22: Source: SSSU, NBU staff estimates.
A23: 45870 | B23: 10.8 | C23: 1 | D23: 6 | E23: 0.4 | F23: 0.9 | G23: 2.5
A24: 45901 | B24: 10.7 | C24: 1.1 | D24: 5.8 | E24: 0.4 | F24: 0.9 | G24: 2.5
A25: 45931 | B25: 10.6 | C25: 1 | D25: 5.8 | E25: 0.4 | F25: 1 | G25: 2.4
A26: 45962 | B26: 10.4 | C26: 1 | D26: 5.8 | E26: 0.4 | F26: 1 | G26: 2.2
A27: 45992 | B27: 9.7 | C27: 0.8 | D27: 5.7 | E27: 0.4 | F27: 0.8 | G27: 2
A28: 46023 | B28: 9.1 | C28: 0.7 | D28: 5.6 | E28: 0.3 | F28: 0.7 | G28: 1.7 | H28: 46023
A29: 46054 | B29: 8.8 | C29: 0.8 | D29: 5.6 | E29: 0.4 | F29: 0.7 | G29: 1.3
A30: 46082 | B30: 8.6 | C30: 0.7 | D30: 5.4 | E30: 0.1 | F30: 1 | G30: 1.3
A31: 46113 | B31: 9.4 | C31: 0.8 | D31: 5.5 | E31: 0.2 | F31: 1.6 | G31: 1.4
A32: 46143 | B32: 10.2 | C32: 1 | D32: 5.6 | E32: 0.2 | F32: 1.9 | G32: 1.5
A33: 46174 | B33: 10.7 | C33: 1.1 | D33: 5.7 | E33: 0.5 | F33: 1.9 | G33: 1.6 | H33: 46174

Sheet 1.7
A1: << | B1: =IF(Content!$E$1=1,B2,B3) -> Алкогольні напої | C1: =IF(Content!$E$1=1,C2,C3) -> Тютюнові вироби | D1: =IF(Content!$E$1=1,D2,D3) -> Послуги ЖКГ | E1: =IF(Content!$E$1=1,E2,E3) -> Транспорт | F1: =IF(Content!$E$1=1,F2,F3) -> Фармацевтична продукція | I1: =IF(Content!$E$1=1,I2,I3) -> Окремі компоненти адміністративної інфляції, % р/р
B2: Алкогольні напої | C2: Тютюнові вироби | D2: Послуги ЖКГ | E2: Транспорт | F2: Фармацевтична продукція | I2: Окремі компоненти адміністративної інфляції, % р/р
B3: Alcoholic beverages | C3: Tobacco products | D3: Utilities | E3: Transport | F3: Pharmaceutical products | I3: Selected components of administered inflation, % yoy
A4: 45292 | B4: 3.4 | C4: 16.1 | D4: 16.1 | E4: 3.7 | F4: 12.1 | H4: 01.24
A5: 45323 | B5: 2.5 | C5: 16.1 | D5: 16 | E5: 3.6 | F5: 12.3
A6: 45352 | B6: 1 | C6: 16.4 | D6: 16 | E6: 3.6 | F6: 13
A7: 45383 | B7: 0.1 | C7: 16.4 | D7: 16 | E7: 4.2 | F7: 14.2
A8: 45413 | B8: -1.2 | C8: 16.5 | D8: 16 | E8: 4.4 | F8: 16
A9: 45444 | B9: -0.9 | C9: 16.8 | D9: 22.8 | E9: 5.6 | F9: 16.7
A10: 45474 | B10: -0.8 | C10: 16.5 | D10: 22.8 | E10: 6.5 | F10: 14.8 | H10: 07.24
A11: 45505 | B11: -0.5 | C11: 16.1 | D11: 22.8 | E11: 7 | F11: 15.7
A12: 45536 | B12: -0.4 | C12: 17.4 | D12: 22.8 | E12: 6.9 | F12: 15.4
A13: 45566 | B13: 0.5 | C13: 19.4 | D13: 22.9 | E13: 6.9 | F13: 15.5
A14: 45597 | B14: 1.1 | C14: 20.8 | D14: 22.9 | E14: 7.4 | F14: 15.6
A15: 45627 | B15: 3.2 | C15: 22.9 | D15: 22.9 | E15: 8.5 | F15: 17.5
A16: 45658 | B16: 3.8 | C16: 24.3 | D16: 23 | E16: 10.1 | F16: 17.9 | H16: 01.25
A17: 45689 | B17: 4.3 | C17: 25.1 | D17: 23 | E17: 11.4 | F17: 19.2
A18: 45717 | B18: 6.1 | C18: 26.4 | D18: 23.9 | E18: 12.7 | F18: 20.7
A19: 45748 | B19: 6.2 | C19: 27.6 | D19: 23.9 | E19: 13.1 | F19: 18.8
A20: 45778 | B20: 6.9 | C20: 28.3 | D20: 23.8 | E20: 13.2 | F20: 17.4 | I20: =IF(Content!$E$1=1,I21,I22) -> Джерело: ДССУ, розрахунки НБУ.
A21: 45809 | B21: 6.6 | C21: 28.4 | D21: 1.1 | E21: 13.2 | F21: 16.8 | I21: Джерело: ДССУ, розрахунки НБУ.
A22: 45839 | B22: 6.7 | C22: 30.1 | D22: 1.1 | E22: 12.5 | F22: 15.9 | H22: 07.25 | I22: Source: SSSU, NBU staff estimates.
A23: 45870 | B23: 5.6 | C23: 30.9 | D23: 1.1 | E23: 11.9 | F23: 14.6
A24: 45901 | B24: 6.6 | C24: 29.3 | D24: 1.1 | E24: 12.1 | F24: 14.7
A25: 45931 | B25: 6.4 | C25: 28.8 | D25: 1.1 | E25: 12.6 | F25: 13.6
A26: 45962 | B26: 6.1 | C26: 28.7 | D26: 1 | E26: 12.2 | F26: 12.2
A27: 45992 | B27: 4.7 | C27: 27.7 | D27: 1 | E27: 10.6 | F27: 10
A28: 46023 | B28: 4.4 | C28: 26.8 | D28: 0.9 | E28: 9.3 | F28: 7.4 | H28: 46023
A29: 46054 | B29: 4.6 | C29: 26.3 | D29: 1 | E29: 8.9 | F29: 1.1
A30: 46082 | B30: 4.2 | C30: 25 | D30: 0.3 | E30: 13.4 | F30: -2.7
A31: 46113 | B31: 4.5 | C31: 24.5 | D31: 0.4 | E31: 21.4 | F31: -3.5
A32: 46143 | B32: 5.5 | C32: 24.6 | D32: 0.4 | E32: 25.2 | F32: -4.5
A33: 46174 | B33: 6.1 | C33: 24.6 | D33: 1.1 | E33: 25.5 | F33: -5.4 | H33: 46174

Sheet 1.8
A1: << | B1: =IF(Content!$E$1=1,B2,B3) -> Банки | C1: =IF(Content!$E$1=1,C2,C3) -> Підприємства | D1: =IF(Content!$E$1=1,D2,D3) -> Домогосподарства | E1: =IF(Content!$E$1=1,E2,E3) -> Фінансові аналітики | F1: =IF(Content!$E$1=1,F2,F3) -> ІСЦ | I1: =IF(Content!$E$1=1,I2,I3) -> Інфляційні очікування на наступні 12 місяців та інфляція в річному вимірі, %
B2: Банки | C2: Підприємства | D2: Домогосподарства | E2: Фінансові аналітики | F2: ІСЦ | I2: Інфляційні очікування на наступні 12 місяців та інфляція в річному вимірі, %
B3: Banks | C3: Corporates | D3: Households | E3: Financial analysts | F3: CPI | I3: 12-month-ahead inflation expectations and inflation in annual terms, %
A4: 45292 | B4: 10.4 | C4: #N/A | D4: 8.7 | E4: 8.2 | F4: 4.7 | G4: 01.24
A5: 45323 | B5: #N/A | C5: 11 | D5: 9.3 | E5: #N/A | F5: 4.3
A6: 45352 | B6: #N/A | C6: #N/A | D6: 8.7 | E6: 8.1 | F6: 3.2
A7: 45383 | B7: 9.3 | C7: #N/A | D7: 6.5 | E7: 7.4 | F7: 3.2
A8: 45413 | B8: #N/A | C8: 9 | D8: 6.5 | E8: #N/A | F8: 3.3
A9: 45444 | B9: #N/A | C9: #N/A | D9: 7.9 | E9: 7.1 | F9: 4.8
A10: 45474 | B10: 8.7 | C10: #N/A | D10: 7.6 | E10: 7.2 | F10: 5.4 | G10: 07.24
A11: 45505 | B11: #N/A | C11: 9.7 | D11: 7.1 | E11: #N/A | F11: 7.5
A12: 45536 | B12: #N/A | C12: #N/A | D12: 7.2 | E12: 7.4 | F12: 8.6
A13: 45566 | B13: 9.2 | C13: #N/A | D13: 8.1 | E13: 7.6 | F13: 9.7
A14: 45597 | B14: #N/A | C14: 10.3 | D14: 7.8 | E14: #N/A | F14: 11.2
A15: 45627 | B15: #N/A | C15: #N/A | D15: 11.3 | E15: 7.2 | F15: 12
A16: 45658 | B16: 9 | C16: #N/A | D16: 11 | E16: 7.8 | F16: 12.9 | G16: 01.25
A17: 45689 | B17: #N/A | C17: 11.5 | D17: 9.9 | E17: 7.8 | F17: 13.4
A18: 45717 | B18: #N/A | C18: #N/A | D18: 9.2 | E18: #N/A | F18: 14.6
A19: 45748 | B19: 9.8 | C19: #N/A | D19: 10.1 | E19: 7.7 | F19: 15.1 | I19: =IF(Content!$E$1=1,I20,I21) -> Джерело: НБУ, Info Sapiens, ДССУ.
A20: 45778 | B20: #N/A | C20: 10.9 | D20: 10.2 | E20: 7.9 | F20: 15.9 | I20: Джерело: НБУ, Info Sapiens, ДССУ.
A21: 45809 | B21: #N/A | C21: #N/A | D21: 10.8 | E21: #N/A | F21: 14.3 | I21: Source: NBU, Info Sapiens, SSSU.
A22: 45839 | B22: 11.6 | C22: #N/A | D22: 10.7 | E22: 7.5 | F22: 14.1 | G22: 07.25
A23: 45870 | B23: #N/A | C23: 11.4 | D23: 10.1 | E23: #N/A | F23: 13.2
A24: 45901 | B24: #N/A | C24: #N/A | D24: 10.8 | E24: 7.2 | F24: 11.9
A25: 45931 | B25: 10 | C25: #N/A | D25: 10.3 | E25: 7.4 | F25: 10.9
A26: 45962 | B26: #N/A | C26: 11.1 | D26: 10.4 | E26: #N/A | F26: 9.3
A27: 45992 | B27: #N/A | C27: #N/A | D27: 10.5 | E27: 7.5 | F27: 8
A28: 46023 | B28: 9.4 | C28: #N/A | D28: 10.9 | E28: 7.5 | F28: 7.4 | G28: 46023
A29: 46054 | B29: #N/A | C29: 11.1 | D29: 13.5 | E29: #N/A | F29: 7.6
A30: 46082 | B30: #N/A | C30: #N/A | D30: 14.4 | E30: 7.7 | F30: 7.9
A31: 46113 | B31: 9.3 | C31: #N/A | D31: 10.9 | E31: 7.6 | F31: 8.6
A32: 46143 | B32: #N/A | C32: 11.6 | D32: 13.7 | E32: #N/A | F32: 8.2
A33: 46174 | B33: #N/A | C33: #N/A | D33: 12.7 | E33: 7.5 | F33: 7.2
A34: 46204 | B34: 8.7 | C34: #N/A | D34: 10 | E34: 7.9 | F34: #N/A | G34: 46204

Sheet 1.9
A1: << | B1: =IF(Content!$E$1=1,B2,B3) -> ІЦВ | C1: =IF(Content!$E$1=1,C2,C3) -> Переробна промисловість | D1: =IF(Content!$E$1=1,D2,D3) -> Добувна промисловість | E1: =IF(Content!$E$1=1,E2,E3) -> Е/е, газ, пара та конд. повітря (п. ш.) | H1: =IF(Content!$E$1=1,H2,H3) -> Індекс цін виробників (ІЦВ) та його компоненти, % р/р
B2: ІЦВ | C2: Переробна промисловість | D2: Добувна промисловість | E2: Е/е, газ, пара та конд. повітря (п. ш.) | H2: Індекс цін виробників (ІЦВ) та його компоненти, % р/р
B3: PPI | C3: Processing industry | D3: Mining industry | E3: Electricity, gas, steam and air cond. supply (RHS) | H3: Producer Price Index (PPI) and its components, % yoy
A4: 45292 | B4: 10.3 | C4: 8.7 | D4: 11.4 | E4: 10.4 | F4: 01.24
A5: 45323 | B5: 7.7 | C5: 8.8 | D5: 3.5 | E5: 7.4
A6: 45352 | B6: -0.2 | C6: 8.1 | D6: -0.3 | E6: -7.8
A7: 45383 | B7: 4.9 | C7: 6.4 | D7: 2.8 | E7: 3.7
A8: 45413 | B8: 14.8 | C8: 6.3 | D8: 9.5 | E8: 23.7
A9: 45444 | B9: 26.7 | C9: 7.2 | D9: 10.8 | E9: 48.1
A10: 45474 | B10: 33.3 | C10: 9.6 | D10: 10.1 | E10: 60.6 | F10: 07.24
A11: 45505 | B11: 31.2 | C11: 9.2 | D11: 7.4 | E11: 56.2
A12: 45536 | B12: 27.1 | C12: 10 | D12: 0.4 | E12: 47.1
A13: 45566 | B13: 24.5 | C13: 11.4 | D13: -0.4 | E13: 39
A14: 45597 | B14: 24.1 | C14: 13.2 | D14: 2.5 | E14: 34.6
A15: 45627 | B15: 27.6 | C15: 14 | D15: 5.8 | E15: 41.4
A16: 45658 | B16: 32.5 | C16: 13.7 | D16: 7.1 | E16: 53 | F16: 01.25
A17: 45689 | B17: 37 | C17: 13 | D17: 7.7 | E17: 65.1
A18: 45717 | B18: 51.9 | C18: 13.2 | D18: 9.8 | E18: 106.4
A19: 45748 | B19: 41.6 | C19: 14.2 | D19: 5.8 | E19: 76.4 | H19: =IF(Content!$E$1=1,H20,H21) -> Джерело: ДССУ.
A20: 45778 | B20: 28.9 | C20: 13.9 | D20: 3 | E20: 45.7 | H20: Джерело: ДССУ.
A21: 45809 | B21: 13.1 | C21: 13.1 | D21: 0.7 | E21: 13.4 | H21: Source: SSSU.
A22: 45839 | B22: 4.7 | C22: 11.5 | D22: 4.4 | E22: -3 | F22: 07.25
A23: 45870 | B23: 7.3 | C23: 11.4 | D23: 5.2 | E23: 2.5
A24: 45901 | B24: 1.3 | C24: 11.1 | D24: 7 | E24: -10.1
A25: 45931 | B25: 5.5 | C25: 10.4 | D25: 4.5 | E25: -0.7
A26: 45962 | B26: 9.9 | C26: 9.2 | D26: 0.9 | E26: 10.7
A27: 45992 | B27: 8.2 | C27: 8.8 | D27: -0.3 | E27: 7.8
A28: 46023 | B28: 11.2 | C28: 8.9 | D28: -1.3 | E28: 15.4 | F28: 01.26
A29: 46054 | B29: 34.5 | C29: 10 | D29: -1.4 | E29: 73.4
A30: 46082 | B30: 36.6 | C30: 11.4 | D30: 3.7 | E30: 75.8
A31: 46113 | B31: 40.2 | C31: 12 | D31: 10.3 | E31: 81.7
A32: 46143 | B32: 45.2 | C32: 13.4 | D32: 10.1 | E32: 94.3
A33: 46174 | B33: 39.1 | C33: 13.8 | D33: 9.9 | E33: 73 | F33: 06.26

Sheet 1.10
A1: << | B1: =IF(Content!$E$1=1,B2,B3) -> Ринок "доба наперед" | C1: =IF(Content!$E$1=1,C2,C3) -> Внутрішньодобовий ринок | D1: =IF(Content!$E$1=1,D2,D3) -> Ринок довгострокових договорів* | G1: =IF(Content!$E$1=1,G2,G3) -> Ціни на е/е для непобутових споживачів, грн/МВт•год
B2: Ринок "доба наперед" | C2: Внутрішньодобовий ринок | D2: Ринок довгострокових договорів* | G2: Ціни на е/е для непобутових споживачів, грн/МВт•год
B3: Day-ahead market | C3: Intraday market | D3: Long-term contracts market* | G3: Electricity prices for non-household consumers, UAH/MWh
A4: 45292 | B4: 3370.3 | C4: 3507.51 | D4: 3752.3 | E4: 01.24
A5: 45323 | B5: 3100.54 | C5: 3285.42 | D5: 3107.6
A6: 45352 | B6: 2908.09 | C6: 3063.26 | D6: 2409
A7: 45383 | B7: 3115.54 | C7: 3406.63 | D7: 2665.2
A8: 45413 | B8: 3941.16 | C8: 4975.95 | D8: 3304.8
A9: 45444 | B9: 4981.94 | C9: 5609.46 | D9: 5484.3
A10: 45474 | B10: 5567.2 | C10: 5725.42 | D10: 5353.1 | E10: 07.24
A11: 45505 | B11: 5497.53 | C11: 5971.35 | D11: 5049.9
A12: 45536 | B12: 5410.71 | C12: 6109.8 | D12: 5022.9
A13: 45566 | B13: 5249.44 | C13: 5568.77 | D13: 5144.7
A14: 45597 | B14: 5276.88 | C14: 5584.1 | D14: 5071.1
A15: 45627 | B15: 5778.6 | C15: 6057.22 | D15: 5057.8
A16: 45658 | B16: 5548.03 | C16: 5839.35 | D16: 5327.4 | E16: 01.25
A17: 45689 | B17: 5872.87 | C17: 6531.23 | D17: 5413.8
A18: 45717 | B18: 5150.66 | C18: 4745.95 | D18: 5611.1 | G18: =IF(Content!$E$1=1,G21,G22) -> * З травня 2026 року дані за середньодекадними значеннями.
A19: 45748 | B19: 4258.63 | C19: 4287.3 | D19: 4782.5 | G19: =IF(Content!$E$1=1,G24,G25) -> Джерело: Українська енергетична біржа, Оператор ринку.
A20: 45778 | B20: 4421.95 | C20: 4216.48 | D20: 3886.9
A21: 45809 | B21: 4664.67 | C21: 4167.84 | D21: 4449.4 | G21: * З травня 2026 року дані за середньодекадними значеннями.
A22: 45839 | B22: 5184.24 | C22: 4943.77 | D22: 4686.2 | E22: 07.25 | G22: * From May 2026 onward, monthly values are based on three 10-day averages
A23: 45870 | B23: 5188.78 | C23: 4913.41 | D23: 5416.4
A24: 45901 | B24: 4196.92 | C24: 4451.85 | D24: 4972.9 | G24: Джерело: Українська енергетична біржа, Оператор ринку.
A25: 45931 | B25: 5986.52 | C25: 6688.41 | D25: 4168.9 | G25: Source: Ukrainian Energy Exchange, Market operator.
A26: 45962 | B26: 6387.89 | C26: 6658.85 | D26: 5209
A27: 45992 | B27: 6648.95 | C27: 6893.16 | D27: 5564.5
A28: 46023 | B28: 8253.26 | C28: 8692.26 | D28: 6102.2 | E28: 01.26
A29: 46054 | B29: 9785.72 | C29: 10282.29 | D29: 9182.4
A30: 46082 | B30: 7075.53 | C30: 6684.63 | D30: 7211.3
A31: 46113 | B31: 5391.3 | C31: 5007.83 | D31: 6006.7
A32: 46143 | B32: 5068.72 | C32: 4946.7 | D32: 5397.77
A33: 46174 | B33: 5599.18 | C33: 5106.08 | D33: 5152.43
A34: 46204 | B34: 4443.89 | C34: 4311.33 | D34: 5330.4 | E34: 07.26

Sheet 1.11
A1: << | B1: =IF(Content!$E$1=1,B2,B3) -> Оброблені продукти | C1: =IF(Content!$E$1=1,C2,C3) -> Послуги | D1: =IF(Content!$E$1=1,D2,D3) -> Одяг і взуття | E1: =IF(Content!$E$1=1,E2,E3) -> Інші непродовольчі товари | H1: =IF(Content!$E$1=1,H2,H3) -> Компоненти БІСЦ, % р/р
B2: Оброблені продукти | C2: Послуги | D2: Одяг і взуття | E2: Інші непродовольчі товари | H2: Компоненти БІСЦ, % р/р
B3: Processed foods | C3: Services | D3: Clothing & Footwear | E3: Other nonfoods | H3: Components of the core CPI, % yoy
A4: 45292 | B4: 5.5 | C4: 10.1 | D4: -6.7 | E4: 1 | F4: 01.24
A5: 45323 | B5: 5.6 | C5: 9.8 | D5: -7 | E5: 0.6
A6: 45352 | B6: 5.3 | C6: 9.7 | D6: -6.7 | E6: 0.4
A7: 45383 | B7: 5.5 | C7: 9.7 | D7: -6.2 | E7: 0.8
A8: 45413 | B8: 5.3 | C8: 9.7 | D8: -6.1 | E8: 1
A9: 45444 | B9: 5.9 | C9: 9.9 | D9: -5.6 | E9: 1.6
A10: 45474 | B10: 6.5 | C10: 10.3 | D10: -4.5 | E10: 2.2 | F10: 07.24
A11: 45505 | B11: 7.4 | C11: 10.5 | D11: -5.1 | E11: 3.1
A12: 45536 | B12: 8.9 | C12: 10.9 | D12: -5.1 | E12: 3.8
A13: 45566 | B13: 10.7 | C13: 11 | D13: -4.6 | E13: 4.6
A14: 45597 | B14: 12.5 | C14: 11.2 | D14: -3.9 | E14: 5.1
A15: 45627 | B15: 14.7 | C15: 12.5 | D15: -4.3 | E15: 5.6
A16: 45658 | B16: 15.9 | C16: 14.2 | D16: -4.3 | E16: 5.9 | F16: 01.25
A17: 45689 | B17: 16.7 | C17: 14.3 | D17: -4 | E17: 5.9
A18: 45717 | B18: 17.3 | C18: 14.6 | D18: -3.6 | E18: 6.3
A19: 45748 | B19: 17.3 | C19: 14.6 | D19: -4.4 | E19: 5.3 | H19: =IF(Content!$E$1=1,H20,H21) -> Джерело: ДССУ, розрахунки НБУ.
A20: 45778 | B20: 18 | C20: 14.6 | D20: -4.8 | E20: 5.4 | H20: Джерело: ДССУ, розрахунки НБУ.
A21: 45809 | B21: 18.2 | C21: 14.4 | D21: -4.5 | E21: 5 | H21: Source: SSSU, NBU staff estimates.
A22: 45839 | B22: 18 | C22: 14 | D22: -5.4 | E22: 4.8 | F22: 07.25
A23: 45870 | B23: 17.7 | C23: 14.1 | D23: -5.7 | E23: 4.2
A24: 45901 | B24: 16.8 | C24: 14.1 | D24: -5.3 | E24: 3.7
A25: 45931 | B25: 15.6 | C25: 13.8 | D25: -6 | E25: 3
A26: 45962 | B26: 13.9 | C26: 13.4 | D26: -6.1 | E26: 2
A27: 45992 | B27: 12.1 | C27: 12.3 | D27: -6.1 | E27: 1
A28: 46023 | B28: 10.8 | C28: 11.2 | D28: -5.4 | E28: 0.5 | F28: 46023
A29: 46054 | B29: 9.9 | C29: 12.3 | D29: -5 | E29: 0.5
A30: 46082 | B30: 10 | C30: 12.8 | D30: -6.1 | E30: 0.5
A31: 46113 | B31: 10.2 | C31: 13.3 | D31: -5.4 | E31: 1.3
A32: 46143 | B32: 10.4 | C32: 13.6 | D32: -5.3 | E32: 1.3
A33: 46174 | B33: 10.4 | C33: 13.7 | D33: -5.4 | E33: 1.6 | F33: 46174

Sheet 1.12
A1: << | B1: =IF(Content!$E$1=1,B2,B3) -> Оброблені продукти | C1: =IF(Content!$E$1=1,C2,C3) -> Послуги | D1: =IF(Content!$E$1=1,D2,D3) -> Одяг і взуття | E1: =IF(Content!$E$1=1,E2,E3) -> Інші непродовольчі товари | I1: =IF(Content!$E$1=1,I2,I3) -> Ануалізовані* зміни основних складових БІСЦ, %
B2: Оброблені продукти | C2: Послуги | D2: Одяг і взуття | E2: Інші непродовольчі товари | I2: Ануалізовані* зміни основних складових БІСЦ, %
B3: Processed foods | C3: Services | D3: Clothing & Footwear | E3: Other nonfoods | I3: Annualized* changes in the main components of the core CPI, %
A4: 45292 | B4: 5.7 | C4: 6.6 | D4: -4.7 | E4: 4.6 | F4: 01.24
A5: 45323 | B5: 9.1 | C5: 7.9 | D5: -5.4 | E5: 2.7
A6: 45352 | B6: 4.9 | C6: 11.3 | D6: -0.8 | E6: 1.4
A7: 45383 | B7: 8.8 | C7: 12.4 | D7: -2.2 | E7: 7.3
A8: 45413 | B8: 4.9 | C8: 12.9 | D8: -3.8 | E8: 3.5
A9: 45444 | B9: 14 | C9: 13.5 | D9: -5.8 | E9: 5.8
A10: 45474 | B10: 13.9 | C10: 13.9 | D10: 4.6 | E10: 4.9 | F10: 07.24 | S10: =IF(Content!$E$1=1,S11,S12) -> Значні перегляди тарифів мобільними операторами
A11: 45505 | B11: 17.9 | C11: 12 | D11: -7.5 | E11: 6.6 | S11: Значні перегляди тарифів мобільними операторами
A12: 45536 | B12: 21.9 | C12: 13.6 | D12: -8.3 | E12: 6.3 | S12: Significant revisions of tariffs by mobile operators
A13: 45566 | B13: 23 | C13: 12.3 | D13: -1.7 | E13: 8.3
A14: 45597 | B14: 26.3 | C14: 10.8 | D14: -3 | E14: 7.8
A15: 45627 | B15: 27.2 | C15: 23.9 | D15: -9.5 | E15: 9
A16: 45658 | B16: 19.9 | C16: 28.1 | D16: -4.3 | E16: 5.9 | F16: 01.25
A17: 45689 | B17: 18.4 | C17: 8.4 | D17: -3 | E17: 3.5
A18: 45717 | B18: 13 | C18: 14.7 | D18: 3.3 | E18: 5.3 | I18: =IF(Content!$E$1=1,I22,I23) -> * Приведена до річного виміру місячна зміна, сезонно скоригована.
A19: 45748 | B19: 10.7 | C19: 12.5 | D19: -11.9 | E19: -2.7 | I19: =IF(Content!$E$1=1,I20,I21) -> Джерело: ДССУ, розрахунки НБУ.
A20: 45778 | B20: 14 | C20: 12.3 | D20: -7.2 | E20: 4.3 | I20: Джерело: ДССУ, розрахунки НБУ.
A21: 45809 | B21: 14.5 | C21: 11.5 | D21: -3.1 | E21: 1.6 | I21: Source: SSSU, NBU staff estimates.
A22: 45839 | B22: 11.4 | C22: 9.6 | D22: -6.9 | E22: 2.1 | F22: 07.25 | I22: * Приведена до річного виміру місячна зміна, сезонно скоригована.
A23: 45870 | B23: 14 | C23: 13.5 | D23: -10.5 | E23: 0.6 | I23: * Annualized monthly change, seasonally adjusted.
A24: 45901 | B24: 10.8 | C24: 12.5 | D24: -2.9 | E24: 0.2
A25: 45931 | B25: 8.8 | C25: 9 | D25: -9.3 | E25: -0.8
A26: 45962 | B26: 5.6 | C26: 6.9 | D26: -4.7 | E26: -3.2
A27: 45992 | B27: 4.4 | C27: 10.1 | D27: -8.9 | E27: -3.7
A28: 46023 | B28: 4.5 | C28: 14 | D28: 4.1 | E28: -0.8 | F28: 46023
A29: 46054 | B29: 7.2 | C29: 21.7 | D29: 0.5 | E29: 3.2
A30: 46082 | B30: 14.1 | C30: 20.6 | D30: -10.2 | E30: 4.3
A31: 46113 | B31: 14.3 | C31: 19.1 | D31: -5.4 | E31: 8.8
A32: 46143 | B32: 17.1 | C32: 16.2 | D32: -5 | E32: 3.8
A33: 46174 | B33: 15.1 | C33: 12.8 | D33: -5.2 | E33: 5.8 | F33: 46174

Sheet 1.13
A1: << | B1: =IF(Content!$E$1=1,B2,B3) -> Номінальна | C1: =IF(Content!$E$1=1,C2,C3) -> Номінальна (оцінка) | D1: =IF(Content!$E$1=1,D2,D3) -> Реальна | E1: =IF(Content!$E$1=1,E2,E3) -> Реальна (оцінка) | H1: =IF(Content!$E$1=1,H2,H3) -> Річна зміна середньої зарплати, %*
B2: Номінальна | C2: Номінальна (оцінка) | D2: Реальна | E2: Реальна (оцінка) | H2: Річна зміна середньої зарплати, %*
B3: Nominal | C3: Nominal (estimate) | D3: Real | E3: Real (estimate) | H3: Annual change in average wage, %*
A4: 44592 | B4: 18.2 | D4: 7.4
A5: 44620 | C5: 18.1 | E5: 6.7
A6: 44651 | C6: 6.4 | E6: -6.4
A7: 44681 | C7: -7.3 | E7: -20.4
A8: 44712 | C8: -3 | E8: -17.8
A9: 44742 | C9: 8.5 | E9: -10.7 | O9: -50
A10: 44773 | C10: 3.5 | E10: -15.3 | O10: 30
A11: 44804 | C11: -0.6 | E11: -19.7
A12: 44834 | C12: 6.1 | E12: -14.9
A13: 44865 | C13: 8 | E13: -14.7
A14: 44895 | C14: 6.6 | E14: -15.7
A15: 44926 | C15: 9 | E15: -13.9
A16: 44957 | C16: 1.1 | E16: -19.7
A17: 44985 | C17: 3.2 | E17: -17.4
A18: 45016 | C18: 12.4 | E18: -7.4 | H18: =IF(Content!$E$1=1,H22,H23) -> * Для місяців, щодо яких немає даних ДССУ, наведено оцінку НБУ.
A19: 45046 | C19: 25 | E19: 6 | H19: =IF(Content!$E$1=1,H20,H21) -> Джерело: ДССУ, НБУ.
A20: 45077 | C20: 25.3 | E20: 8.7 | H20: Джерело: ДССУ, НБУ.
A21: 45107 | C21: 25.1 | E21: 10.9 | H21: Source: SSSU, NBU.
A22: 45138 | C22: 21.3 | E22: 9 | H22: * Для місяців, щодо яких немає даних ДССУ, наведено оцінку НБУ.
A23: 45169 | C23: 23.8 | E23: 14 | H23: * For months for which there is no data from the SSSU, the NBU’s estimate is provided.
A24: 45199 | C24: 23.1 | E24: 14.9
A25: 45230 | C25: 18 | E25: 12
A26: 45260 | C26: 18.3 | E26: 12.5
A27: 45291 | C27: 14.5 | E27: 8.9
A28: 45322 | B28: 24.2 | C28: 24.2 | D28: 18.7 | E28: 18.7
A29: 45351 | B29: 22.7 | D29: 17.6
A30: 45382 | B30: 21.2 | C30: 21.2 | D30: 17.4 | E30: 17.4
A31: 45412 | C31: 32 | E31: 27.9
A32: 45443 | C32: 26.6 | E32: 22.6
A33: 45473 | C33: 10.9 | E33: 5.8
A34: 45504 | C34: 21.2 | E34: 15
A35: 45535 | C35: 24.4 | E35: 15.7
A36: 45565 | C36: 22.2 | E36: 12.5
A37: 45596 | C37: 26.2 | E37: 15
A38: 45626 | C38: 27.6 | E38: 14.8
A39: 45657 | C39: 24.9 | E39: 11.5
A40: 45688 | B40: 25.5 | C40: 25.5 | D40: 11.2 | E40: 11.2
...

Sheet 1.14
A1: << | B1: =IF(Content!$E$1=1,B2,B3) -> Перукарні та манікюр | C1: =IF(Content!$E$1=1,C2,C3) -> Готелі та пансіонати | D1: =IF(Content!$E$1=1,D2,D3) -> Оренда житла | E1: =IF(Content!$E$1=1,E2,E3) -> Послуги з утримання та ремонту житла | F1: =IF(Content!$E$1=1,F2,F3) -> Мобільний зв'язок та інтернет | I1: =IF(Content!$E$1=1,I2,I3) -> Зміна цін на окремі групи послуг, % р/р
B2: Перукарні та манікюр | C2: Готелі та пансіонати | D2: Оренда житла | E2: Послуги з утримання та ремонту житла | F2: Мобільний зв'язок та інтернет | I2: Зміна цін на окремі групи послуг, % р/р
B3: Hair salons and manicure | C3: Hotels and holiday resorts | D3: Housing rentals | E3: Dwelling maintenance and repair services | F3: Mobile communications and the internet | I3: Changes in prices for selected service groups, % yoy
A4: 45292 | B4: 14.9 | C4: 9.8 | D4: 9 | E4: 10.1 | F4: 4.5 | H4: 01.24
A5: 45323 | B5: 15 | C5: 11.1 | D5: 9.5 | E5: 10.1 | F5: 3.9
A6: 45352 | B6: 15.6 | C6: 10.5 | D6: 9.5 | E6: 10.1 | F6: 3.3
A7: 45383 | B7: 16.4 | C7: 9.4 | D7: 9.4 | E7: 11.2 | F7: 3.1
A8: 45413 | B8: 15.1 | C8: 10 | D8: 9.6 | E8: 11.6 | F8: 3.1
A9: 45444 | B9: 14.5 | C9: 9.6 | D9: 9.1 | E9: 11.3 | F9: 3.6
A10: 45474 | B10: 14.7 | C10: 11.1 | D10: 9.1 | E10: 11.3 | F10: 5.5 | H10: 07.24
A11: 45505 | B11: 15.6 | C11: 12 | D11: 7.9 | E11: 11.6 | F11: 6.1
A12: 45536 | B12: 15.7 | C12: 12 | D12: 8.6 | E12: 11.9 | F12: 6.5
A13: 45566 | B13: 16.3 | C13: 11.9 | D13: 8.1 | E13: 12.6 | F13: 6.8
A14: 45597 | B14: 16.5 | C14: 11.4 | D14: 8 | E14: 12 | F14: 7
A15: 45627 | B15: 17.7 | C15: 11.7 | D15: 7.8 | E15: 11.7 | F15: 12.6
A16: 45658 | B16: 17.5 | C16: 12.4 | D16: 7.4 | E16: 11.8 | F16: 24.8 | H16: 01.25
A17: 45689 | B17: 17.2 | C17: 11.1 | D17: 7.6 | E17: 11.6 | F17: 25.2
A18: 45717 | B18: 16.5 | C18: 11.5 | D18: 7.6 | E18: 11.9 | F18: 24.3
A19: 45748 | B19: 15.7 | C19: 12 | D19: 7.5 | E19: 11.2 | F19: 24.3 | I19: =IF(Content!$E$1=1,I20,I21) -> Джерело: ДССУ, розрахунки НБУ.
A20: 45778 | B20: 15.8 | C20: 12.2 | D20: 7.3 | E20: 10.9 | F20: 24.3 | I20: Джерело: ДССУ, розрахунки НБУ.
A21: 45809 | B21: 16.2 | C21: 13.3 | D21: 7.3 | E21: 10.7 | F21: 22.5 | I21: Source: SSSU, NBU staff estimates.
A22: 45839 | B22: 16.2 | C22: 14.6 | D22: 7.2 | E22: 11.3 | F22: 19.9 | H22: 07.25
A23: 45870 | B23: 15.3 | C23: 13.4 | D23: 7.3 | E23: 11.1 | F23: 22.8
A24: 45901 | B24: 16 | C24: 12.1 | D24: 6.6 | E24: 10.9 | F24: 22.7
A25: 45931 | B25: 15.6 | C25: 10.5 | D25: 6.8 | E25: 9 | F25: 22.4
A26: 45962 | B26: 15.5 | C26: 10.7 | D26: 6.4 | E26: 8.7 | F26: 22.2
A27: 45992 | B27: 14.9 | C27: 11.3 | D27: 6.6 | E27: 8.8 | F27: 16
A28: 46023 | B28: 14.2 | C28: 10.1 | D28: 6.6 | E28: 8.6 | F28: 9.8 | G28: 46023 | H28: 46023
A29: 46054 | B29: 14.7 | C29: 11.8 | D29: 6.6 | E29: 8.4 | F29: 16.3
A30: 46082 | B30: 16.2 | C30: 11.7 | D30: 7.1 | E30: 8.2 | F30: 19.5
A31: 46113 | B31: 17.3 | C31: 13.2 | D31: 7.7 | E31: 9.2 | F31: 19.5
A32: 46143 | B32: 17.6 | C32: 13.5 | D32: 8.9 | E32: 9.2 | F32: 19.5
A33: 46174 | B33: 18.4 | C33: 13.7 | D33: 10.2 | E33: 12.2 | F33: 19.4 | G33: 46174 | H33: 46174

Sheet 1.15
A1: << | E1: =IF(Content!$E$1=1,E2,E3) -> Теплова карта БІСЦ*, %
E2: Теплова карта БІСЦ*, %
E3: Core CPI heatmap*, %
A4: 44197 | B4: 100 | D4: 01.21
A5: 44228 | B5: 100
A6: 44256 | B6: 100
A7: 44287 | B7: 100
A8: 44317 | B8: 100
A9: 44348 | B9: 100
A10: 44378 | B10: 100
A11: 44409 | B11: 100
A12: 44440 | B12: 100
A13: 44470 | B13: 100
A14: 44501 | B14: 100
A15: 44531 | B15: 100
A16: 44562 | B16: 100 | D16: 01.22 | E16: =IF(Content!$E$1=1,E17,E18) -> Стандартизовані оцінки (z-scores)
A17: 44593 | B17: 100 | E17: Стандартизовані оцінки (z-scores)
A18: 44621 | B18: 100 | E18: Standardized scores (z-scores)
A19: 44652 | B19: 100 | J19: -3 | K19: 3
A20: 44682 | B20: 100
A21: 44713 | B21: 100 | E21: =IF(Content!$E$1=1,E28,E29) -> * Кольори надають інформацію про те, чи перебуває інфляція окремого компонента вище середнього (червоний) за відповідний період або нижче (синій); насиченість кольорів позначає ступінь такої події, виміряну в стандартних відхиленнях; розмір клітинок позначає розподіл значень між індикаторами.
A22: 44743 | B22: 100
A23: 44774 | B23: 100
A24: 44805 | B24: 100 | E24: =IF(Content!$E$1=1,E26,E27) -> Джерело: ДССУ, розрахунки НБУ.
A25: 44835 | B25: 100
A26: 44866 | B26: 100 | E26: Джерело: ДССУ, розрахунки НБУ.
A27: 44896 | B27: 100 | E27: Source: SSSU, NBU staff estimates.
A28: 44927 | B28: 100 | D28: 01.23 | E28: * Кольори надають інформацію про те, чи перебуває інфляція окремого компонента вище середнього (червоний) за відповідний період або нижче (синій); насиченість кольорів позначає ступінь такої події, виміряну в стандартних відхиленнях; розмір клітинок позначає розподіл значень між індикаторами.
A29: 44958 | B29: 100 | E29: * The colors on the heatmap provide information on whether the inflation of a particular component is above the average (red) for the respective period or below it (blue); the saturation of the colors indicates the degree of such an event measured in standard deviations, and the size of the cells indicates the distribution of values between the indicators.
A30: 44986 | B30: 100
A31: 45017 | B31: 100
A32: 45047 | B32: 100
A33: 45078 | B33: 100
A34: 45108 | B34: 100
A35: 45139 | B35: 100
A36: 45170 | B36: 100
A37: 45200 | B37: 100
A38: 45231 | B38: 100
A39: 45261 | B39: 100
A40: 45292 | B40: 100 | D40: 01.24
...

Sheet 1.16
A1: << | B1: =IF(Content!$E$1=1,B2,B3) -> ІСЦ | C1: =IF(Content!$E$1=1,C2,C3) -> Базовий ІСЦ | E1: =IF(Content!$E$1=1,E2,E3) -> Ануалізовані* зміни ІСЦ та БІСЦ, %
B2: ІСЦ | C2: Базовий ІСЦ | E2: Ануалізовані* зміни ІСЦ та БІСЦ, %
B3: CPI | C3: Core CPI | E3: Annualised* changes in the CPI and Core CPI, %
A4: 45292 | B4: 4.4 | C4: 6.7 | D4: 01.24
A5: 45323 | B5: 4.1 | C5: 5.6
A6: 45352 | B6: 0.1 | C6: 4.6
A7: 45383 | B7: 3.5 | C7: 8.8
A8: 45413 | B8: 3 | C8: 6.2
A9: 45444 | B9: 22.6 | C9: 10.4
A10: 45474 | B10: 13 | C10: 13 | D10: 07.24
A11: 45505 | B11: 20.3 | C11: 11.8
A12: 45536 | B12: 18.4 | C12: 12.6
A13: 45566 | B13: 16.8 | C13: 14.3
A14: 45597 | B14: 21.7 | C14: 15.1
A15: 45627 | B15: 16.7 | C15: 18.4
A16: 45658 | B16: 14.6 | C16: 18.1 | D16: 01.25
A17: 45689 | B17: 11.7 | C17: 8.7
A18: 45717 | B18: 13.4 | C18: 10.6
A19: 45748 | B19: 10.6 | C19: 6.4 | E19: =IF(Content!$E$1=1,E22,E23) -> * Приведена до річного виміру місячна зміна, сезонно скоригована.
A20: 45778 | B20: 13.6 | C20: 9.5 | E20: =IF(Content!$E$1=1,E25,E26) -> Джерело: ДССУ, розрахунки НБУ.
A21: 45809 | B21: 4.3 | C21: 8.5
A22: 45839 | B22: 10.9 | C22: 7.1 | D22: 07.25 | E22: * Приведена до річного виміру місячна зміна, сезонно скоригована.
A23: 45870 | B23: 8.2 | C23: 8.5 | E23: * Annualized monthly change, seasonally adjusted.
A24: 45901 | B24: 2.9 | C24: 7
A25: 45931 | B25: 4.7 | C25: 4.8 | E25: Джерело: ДССУ, розрахунки НБУ.
A26: 45962 | B26: 0.8 | C26: 3.3 | E26: Source: SSSU, NBU staff estimates.
A27: 45992 | B27: 1.6 | C27: 2.2
A28: 46023 | B28: 8.4 | C28: 7.1 | D28: 01.26
A29: 46054 | B29: 15.8 | C29: 8.5
A30: 46082 | B30: 17.5 | C30: 11.6
A31: 46113 | B31: 20.8 | C31: 13
A32: 46143 | B32: 9.5 | C32: 11.4
A33: 46174 | B33: -2.5 | C33: 11.1 | D33: 06.26

Sheet 1.17
A1: << | B1: =IF(Content!$E$1=1,B2,B3) -> Річна зміна | C1: =IF(Content!$E$1=1,C2,C3) -> Річна зміна (попередній прогноз) | D1: =IF(Content!$E$1=1,D2,D3) -> Зміна за квартал | E1: =IF(Content!$E$1=1,E2,E3) -> Зміна за квартал, с/с | H1: =IF(Content!$E$1=1,H2,H3) -> Базовий ІСЦ на кінець періоду, %
B2: Річна зміна | C2: Річна зміна (попередній прогноз) | D2: Зміна за квартал | E2: Зміна за квартал, с/с | H2: Базовий ІСЦ на кінець періоду, %
B3: Annual change | C3: Annual change (previous forecast) | D3: Quarterly change | E3: Quarterly change, sa | H3: Core inflation at the end of period, %
A4: I.24 | B4: 4.2 | D4: 1.8 | E4: 1.3
B5: 5 | D5: 1.5 | E5: 2.2
B6: 7.3 | D6: 3.1 | E6: 2.8
B7: 10.7 | D7: 3.8 | E7: 3.9
A8: I.25 | B8: 12.4 | D8: 3.4 | E8: 2.9
B9: 12.1 | D9: 1.2 | E9: 2
B10: 11 | D10: 2.1 | E10: 1.8
B11: 8 | D11: 1 | E11: 1
A12: I.26 | B12: 7.1 | C12: 7.1 | D12: 2.7 | E12: 2.1
B13: 8.1 | C13: 7.2 | D13: 2.1 | E13: 2.9
B14: 8.3 | C14: 7 | D14: 2.3 | E14: 2
B15: 9.2 | C15: 7.2 | D15: 1.9 | E15: 1.9
A16: I.27 | B16: 8.7 | C16: 6.3 | D16: 2.2 | E16: 1.6
B17: 7.2 | C17: 5.3 | D17: 0.6 | E17: 1.4
B18: 6.1 | C18: 4.6 | D18: 1.3 | E18: 1
B19: 5.1 | C19: 4.3 | D19: 0.9 | E19: 1 | H19: =IF(Content!$E$1=1,H20,H21) -> Джерело: ДССУ, розрахунки НБУ.
A20: I.28 | B20: 4.3 | C20: 4 | D20: 1.4 | E20: 0.8 | H20: Джерело: ДССУ, розрахунки НБУ.
B21: 3.8 | C21: 3.7 | D21: 0 | E21: 0.8 | H21: Source: SSSU, NBU staff estimates.
B22: 3.4 | C22: 3.3 | D22: 1 | E22: 0.7
A23: IV.28 | B23: 3.3 | C23: 3.2 | D23: 0.7 | E23: 0.8

Sheet 1.18
A1: << | B1: =IF(Content!$E$1=1,B2,B3) -> Оброблені продукти | C1: =IF(Content!$E$1=1,C2,C3) -> Сирі продукти | F1: =IF(Content!$E$1=1,F2,F3) -> Компоненти продовольчої інфляції, зміна на кінець періоду, % р/р
B2: Оброблені продукти | C2: Сирі продукти | F2: Компоненти продовольчої інфляції, зміна на кінець періоду, % р/р
B3: Processed foods | C3: Raw foods | F3: Food inflation components at the end of period, % yoy
A4: I.23 | B4: 23.5 | C4: 31.6
B5: 14.7 | C5: 18.2
B6: 10.6 | C6: 0.3
B7: 5.9 | C7: 2.2
A8: I.24 | B8: 5.3 | C8: -4.9
B9: 5.9 | C9: -6.5
B10: 8.9 | C10: 7.1
B11: 14.7 | C11: 13.2
A12: I.25 | B12: 17.3 | C12: 17
B13: 18.2 | C13: 28.7
B14: 16.8 | C14: 18.1
B15: 12.1 | C15: 7.4
A16: I.26 | B16: 10 | C16: 8.4
B17: 10.4 | C17: -0.2
B18: 9.9 | C18: 4.6 | F18: =IF(Content!$E$1=1,F24,F25) -> Джерело: ДССУ, розрахунки НБУ.
B19: 9.8 | C19: 8.3
A20: I.27 | B20: 10 | C20: 7.4
B21: 7.9 | C21: 9.5
B22: 6.3 | C22: 6.7
B23: 4.9 | C23: 5.5
A24: I.28 | B24: 4 | C24: 4.6 | F24: Джерело: ДССУ, розрахунки НБУ.
